{
  "nbformat": 4,
  "nbformat_minor": 0,
  "metadata": {
    "colab": {
      "provenance": [],
      "authorship_tag": "ABX9TyPRSs05odPvamrPiZLwHqA4",
      "include_colab_link": true
    },
    "kernelspec": {
      "name": "python3",
      "display_name": "Python 3"
    },
    "language_info": {
      "name": "python"
    }
  },
  "cells": [
    {
      "cell_type": "markdown",
      "metadata": {
        "id": "view-in-github",
        "colab_type": "text"
      },
      "source": [
        "<a href=\"https://colab.research.google.com/github/scottthomaswx/ProjectsInProgress/blob/main/FVCOM.ipynb\" target=\"_parent\"><img src=\"https://colab.research.google.com/assets/colab-badge.svg\" alt=\"Open In Colab\"/></a>"
      ]
    },
    {
      "cell_type": "markdown",
      "source": [
        "#Install Needed Packages"
      ],
      "metadata": {
        "id": "saIM7gKq7CHs"
      }
    },
    {
      "cell_type": "code",
      "execution_count": 169,
      "metadata": {
        "colab": {
          "base_uri": "https://localhost:8080/"
        },
        "collapsed": true,
        "cellView": "form",
        "id": "nyEi6cms6UG7",
        "outputId": "60243a99-4161-4a2c-fd92-db2b907eff9d"
      },
      "outputs": [
        {
          "output_type": "stream",
          "name": "stdout",
          "text": [
            "\n",
            "Usage:   \n",
            "  pip3 install [options] <requirement specifier> [package-index-options] ...\n",
            "  pip3 install [options] -r <requirements file> [package-index-options] ...\n",
            "  pip3 install [options] [-e] <vcs project url> ...\n",
            "  pip3 install [options] [-e] <local project path> ...\n",
            "  pip3 install [options] <archive url/path> ...\n",
            "\n",
            "no such option: -u\n",
            "Requirement already satisfied: cfgrib in /usr/local/lib/python3.11/dist-packages (0.9.15.0)\n",
            "Requirement already satisfied: attrs>=19.2 in /usr/local/lib/python3.11/dist-packages (from cfgrib) (24.3.0)\n",
            "Requirement already satisfied: click in /usr/local/lib/python3.11/dist-packages (from cfgrib) (8.1.8)\n",
            "Requirement already satisfied: eccodes>=0.9.8 in /usr/local/lib/python3.11/dist-packages (from cfgrib) (2.39.1)\n",
            "Requirement already satisfied: numpy in /usr/local/lib/python3.11/dist-packages (from cfgrib) (1.26.4)\n",
            "Requirement already satisfied: cffi in /usr/local/lib/python3.11/dist-packages (from eccodes>=0.9.8->cfgrib) (1.17.1)\n",
            "Requirement already satisfied: findlibs in /usr/local/lib/python3.11/dist-packages (from eccodes>=0.9.8->cfgrib) (0.0.5)\n",
            "Requirement already satisfied: pycparser in /usr/local/lib/python3.11/dist-packages (from cffi->eccodes>=0.9.8->cfgrib) (2.22)\n",
            "Reading package lists... Done\n",
            "Building dependency tree... Done\n",
            "Reading state information... Done\n",
            "libeccodes0 is already the newest version (2.24.2-1).\n",
            "0 upgraded, 0 newly installed, 0 to remove and 49 not upgraded.\n",
            "\u001b[31mERROR: Could not find a version that satisfies the requirement PIL (from versions: none)\u001b[0m\u001b[31m\n",
            "\u001b[0m\u001b[31mERROR: No matching distribution found for PIL\u001b[0m\u001b[31m\n",
            "\u001b[0m\u001b[31mERROR: Could not find a version that satisfies the requirement os (from versions: none)\u001b[0m\u001b[31m\n",
            "\u001b[0m\u001b[31mERROR: No matching distribution found for os\u001b[0m\u001b[31m\n",
            "\u001b[0m"
          ]
        }
      ],
      "source": [
        "# @title\n",
        "!pip install datetime --quiet\n",
        "!pip install numpy --quiet\n",
        "!pip install matplotlib  -quiet\n",
        "!pip install cartopy --quiet\n",
        "!pip install xarray[complete] --quiet\n",
        "!pip install metpy --quiet\n",
        "!pip install pandas --quiet\n",
        "!pip install cfgrib\n",
        "!apt-get install -y libeccodes0\n",
        "!pip install PIL"
      ]
    },
    {
      "cell_type": "code",
      "source": [
        "import requests\n",
        "from datetime import datetime\n",
        "import numpy as np\n",
        "import matplotlib.pyplot as plt\n",
        "import matplotlib\n",
        "import matplotlib.animation as animation\n",
        "import cartopy.crs as ccrs\n",
        "import xarray as xr\n",
        "from metpy import units\n",
        "import cartopy.feature as cfeature\n",
        "import pandas as pd\n",
        "from metpy.plots import USCOUNTIES\n",
        "import os\n",
        "from PIL import Image\n",
        "!rm -rf img_files\n",
        "!rm -rf fvcom_data\n",
        "!mkdir fvcom_data\n",
        "!mkdir img_files"
      ],
      "metadata": {
        "colab": {
          "base_uri": "https://localhost:8080/"
        },
        "id": "x2az9mMC6xNk",
        "outputId": "c34f0d0b-6e42-46a7-e55a-ee0d3ffbe78c"
      },
      "execution_count": 171,
      "outputs": [
        {
          "output_type": "stream",
          "name": "stdout",
          "text": [
            "mkdir: cannot create directory ‘fvcom_data’: File exists\n",
            "mkdir: cannot create directory ‘img_files’: File exists\n"
          ]
        }
      ]
    },
    {
      "cell_type": "code",
      "source": [
        "year = datetime.now().year\n",
        "month = datetime.now().month\n",
        "day = datetime.now().day\n",
        "hour = datetime.now().hour\n",
        "fhour_list = np.arange(0,72,1)\n",
        "q=0\n",
        "if hour < 16:\n",
        "  run_hour = '00'\n",
        "else:\n",
        "  run_hour = '12'"
      ],
      "metadata": {
        "id": "2jrawhew63rA"
      },
      "execution_count": 96,
      "outputs": []
    },
    {
      "cell_type": "code",
      "source": [
        "url1 = f'https://noaa-nos-ofs-pds.s3.amazonaws.com/lmhofs/netcdf/{year}/{month:02}/{day:02}/lmhofs.t{run_hour}z.{year}{month:02}{day:02}.stations.forecast.nc'\n",
        "r1 = requests.get(url1)\n",
        "file1= f'/content/fvcom_data/{year}{month}{day}.t{run_hour}z.fvcom.station.nc'\n",
        "with open(file1, 'wb') as f1:\n",
        "      f1.write(r1.content)"
      ],
      "metadata": {
        "id": "OMQF6IX3-E_I"
      },
      "execution_count": 115,
      "outputs": []
    },
    {
      "cell_type": "code",
      "source": [
        "fvcom_stations = xr.open_mfdataset('/content/fvcom_data/*station*nc', engine=\"netcdf4\", combine='nested', concat_dim='time', decode_times=False)"
      ],
      "metadata": {
        "id": "hFEJj0DF-d3X"
      },
      "execution_count": 111,
      "outputs": []
    },
    {
      "cell_type": "code",
      "source": [
        "BIV = fvcom_stations.isel(station=np.where(fvcom_stations.name_station.values == 9087031)[0])\n",
        "LDM = fvcom_stations.isel(station=np.where(fvcom_stations.name_station.values == 9087032)[0])"
      ],
      "metadata": {
        "id": "hGRiSeiIDmub"
      },
      "execution_count": 112,
      "outputs": []
    },
    {
      "cell_type": "code",
      "source": [
        "while q < len(fhour_list):\n",
        "  url1 = f'https://noaa-nos-ofs-pds.s3.amazonaws.com/lmhofs/netcdf/{year}/{month:02}/{day:02}/lmhofs.t{run_hour}z.{year}{month:02}{day:02}.regulargrid.f{fhour_list[q]:03}.nc'\n",
        "  r1 = requests.get(url1)\n",
        "  file1= f'/content/fvcom_data/{year}{month}{day}.t{run_hour}z.fvcom.f{fhour_list[q]:03}.nc'\n",
        "  with open(file1, 'wb') as f1:\n",
        "        f1.write(r1.content)\n",
        "  q+=1"
      ],
      "metadata": {
        "id": "lvBL8tiuIKC2"
      },
      "execution_count": 119,
      "outputs": []
    },
    {
      "cell_type": "code",
      "source": [
        "fvcom_datagrid = xr.open_mfdataset('./fvcom_data/*f*nc', engine=\"netcdf4\",\n",
        "                        concat_dim=\"time\", combine='nested')\n",
        "fvcom_datagrid = fvcom_datagrid.isel(Depth=0)\n",
        "water_level = fvcom_datagrid['zetatomllw'].metpy.convert_units('ft')"
      ],
      "metadata": {
        "id": "y5uZw51tIe0g"
      },
      "execution_count": 126,
      "outputs": []
    },
    {
      "cell_type": "code",
      "source": [
        "l=0\n",
        "colors = ['#deebf7', '#deebf7','#deebf7', '#9dc3e6', '#9dc3e6', '#0070c0',\n",
        "          '#0070c0', '#060082','#060082', '#81e78d', '#81e78d', '#00b050',\n",
        "          '#00b050', '#ffff00','#ff9900', '#ff0000', '#ffb6c1', '#7030a0']\n",
        "cmap_plot = matplotlib.colors.LinearSegmentedColormap.from_list(\"\",colors)\n",
        "levels = [-2.0,-1.5,-1.0,-0.5,0,0.5,1,1.5,2,2.5,3,3.5,4,4.5,5,5.5,6,6.5,7]\n",
        "while l < len(water_level['time']):\n",
        "  fig = plt.figure(figsize=(14,8), facecolor='white', edgecolor = 'black', linewidth = 6)\n",
        "  ax=fig.add_subplot(1,1,1, projection=ccrs.PlateCarree())\n",
        "  ax.set_extent([-89,-85,41.5, 46])\n",
        "  waterht = ax.contourf(water_level.Longitude, water_level.Latitude, water_level.isel(time=l), levels = levels, cmap = cmap_plot)\n",
        "  waterhtcon = ax.contour(water_level.Longitude, water_level.Latitude, water_level.isel(time=l), colors = 'white', linewidths = 1,levels = levels)\n",
        "  ax.clabel(waterhtcon, fontsize = 16, colors = 'white')\n",
        "  cbar = plt.colorbar(waterht, shrink=0.9, orientation = 'vertical')\n",
        "  cbar.set_label('Height Above Low Water Level (ft)', rotation=270)\n",
        "  ax.coastlines(color='black',resolution='10m')\n",
        "  ax.add_feature(cfeature.STATES.with_scale('50m'),edgecolor='darkgray')\n",
        "  ax.add_feature(USCOUNTIES, facecolor='None', edgecolor='lightgray', alpha = 0.8, zorder = 0)\n",
        "  plt.title(f'FVCOM Height Above Low Water FHR{l:02}', loc = 'left')\n",
        "  plt.title(f'Run:{year}-{month}-{day} {run_hour}z', loc = 'right')\n",
        "  plt.figtext(0.53, 0.07, f'Advisory: +5.0 Ft', ha='left', weight='bold', color = '#ff9900', fontsize=15)\n",
        "  plt.figtext(0.36, 0.07, f'Warning: +5.5 Ft', ha='left', weight='bold', color = 'red', fontsize=15)\n",
        "\n",
        "  plt.savefig(f'/content/img_files/fvcom_waterlevel_{year}_{month}_{day}_{run_hour}_FHR{l:02}.png', bbox_inches = 'tight')\n",
        "  l+=1"
      ],
      "metadata": {
        "colab": {
          "base_uri": "https://localhost:8080/"
        },
        "collapsed": true,
        "id": "imDJVR49LOnA",
        "outputId": "5512aa92-0e33-461f-df99-42ca031b71f1"
      },
      "execution_count": null,
      "outputs": [
        {
          "output_type": "stream",
          "name": "stderr",
          "text": [
            "ERROR:root:Internal Python error in the inspect module.\n",
            "Below is the traceback from this internal error.\n",
            "\n",
            "ERROR:root:Internal Python error in the inspect module.\n",
            "Below is the traceback from this internal error.\n",
            "\n",
            "ERROR:root:Internal Python error in the inspect module.\n",
            "Below is the traceback from this internal error.\n",
            "\n"
          ]
        },
        {
          "output_type": "stream",
          "name": "stdout",
          "text": [
            "Traceback (most recent call last):\n",
            "  File \"/usr/local/lib/python3.11/dist-packages/IPython/core/interactiveshell.py\", line 3553, in run_code\n",
            "    exec(code_obj, self.user_global_ns, self.user_ns)\n",
            "  File \"<ipython-input-179-de16e834fe6e>\", line 11, in <cell line: 0>\n",
            "    waterht = ax.contourf(water_level.Longitude, water_level.Latitude, water_level.isel(time=l), levels = levels, cmap = cmap_plot)\n",
            "              ^^^^^^^^^^^^^^^^^^^^^^^^^^^^^^^^^^^^^^^^^^^^^^^^^^^^^^^^^^^^^^^^^^^^^^^^^^^^^^^^^^^^^^^^^^^^^^^^^^^^^^^^^^^^^^^^^^^^^\n",
            "  File \"/usr/local/lib/python3.11/dist-packages/cartopy/mpl/geoaxes.py\", line 306, in wrapper\n",
            "    return func(self, *args, **kwargs)\n",
            "           ^^^^^^^^^^^^^^^^^^^^^^^^^^^\n",
            "  File \"/usr/local/lib/python3.11/dist-packages/cartopy/mpl/geoaxes.py\", line 350, in wrapper\n",
            "    return func(self, *args, **kwargs)\n",
            "           ^^^^^^^^^^^^^^^^^^^^^^^^^^^\n",
            "  File \"/usr/local/lib/python3.11/dist-packages/cartopy/mpl/geoaxes.py\", line 1646, in contourf\n",
            "    result = super().contourf(*args, **kwargs)\n",
            "             ^^^^^^^^^^^^^^^^^^^^^^^^^^^^^^^^^\n",
            "  File \"/usr/local/lib/python3.11/dist-packages/matplotlib/__init__.py\", line 1521, in inner\n",
            "    return func(\n",
            "           ^^^^^\n",
            "  File \"/usr/local/lib/python3.11/dist-packages/matplotlib/axes/_axes.py\", line 6760, in contourf\n",
            "    contours = mcontour.QuadContourSet(self, *args, **kwargs)\n",
            "               ^^^^^^^^^^^^^^^^^^^^^^^^^^^^^^^^^^^^^^^^^^^^^^\n",
            "  File \"/usr/local/lib/python3.11/dist-packages/matplotlib/contour.py\", line 708, in __init__\n",
            "    kwargs = self._process_args(*args, **kwargs)\n",
            "             ^^^^^^^^^^^^^^^^^^^^^^^^^^^^^^^^^^^\n",
            "  File \"/usr/local/lib/python3.11/dist-packages/matplotlib/contour.py\", line 1326, in _process_args\n",
            "    x, y, z = self._contour_args(args, kwargs)\n",
            "              ^^^^^^^^^^^^^^^^^^^^^^^^^^^^^^^^\n",
            "  File \"/usr/local/lib/python3.11/dist-packages/matplotlib/contour.py\", line 1366, in _contour_args\n",
            "    x, y, z = self._check_xyz(x, y, z_orig, kwargs)\n",
            "              ^^^^^^^^^^^^^^^^^^^^^^^^^^^^^^^^^^^^^\n",
            "  File \"/usr/local/lib/python3.11/dist-packages/matplotlib/contour.py\", line 1387, in _check_xyz\n",
            "    x = np.asarray(x, dtype=np.float64)\n",
            "        ^^^^^^^^^^^^^^^^^^^^^^^^^^^^^^^\n",
            "  File \"/usr/local/lib/python3.11/dist-packages/xarray/core/common.py\", line 180, in __array__\n",
            "    return np.array(self.values, dtype=dtype, copy=copy)\n",
            "                    ^^^^^^^^^^^\n",
            "  File \"/usr/local/lib/python3.11/dist-packages/xarray/core/dataarray.py\", line 814, in values\n",
            "    return self.variable.values\n",
            "           ^^^^^^^^^^^^^^^^^^^^\n",
            "  File \"/usr/local/lib/python3.11/dist-packages/xarray/core/variable.py\", line 565, in values\n",
            "    return _as_array_or_item(self._data)\n",
            "           ^^^^^^^^^^^^^^^^^^^^^^^^^^^^^\n",
            "  File \"/usr/local/lib/python3.11/dist-packages/xarray/core/variable.py\", line 362, in _as_array_or_item\n",
            "    data = np.asarray(data)\n",
            "           ^^^^^^^^^^^^^^^^\n",
            "  File \"/usr/local/lib/python3.11/dist-packages/dask/array/core.py\", line 1697, in __array__\n",
            "    x = self.compute()\n",
            "        ^^^^^^^^^^^^^^\n",
            "  File \"/usr/local/lib/python3.11/dist-packages/dask/base.py\", line 372, in compute\n",
            "    (result,) = compute(self, traverse=False, **kwargs)\n",
            "                ^^^^^^^^^^^^^^^^^^^^^^^^^^^^^^^^^^^^^^^\n",
            "  File \"/usr/local/lib/python3.11/dist-packages/dask/base.py\", line 653, in compute\n",
            "    dsk = collections_to_dsk(collections, optimize_graph, **kwargs)\n",
            "          ^^^^^^^^^^^^^^^^^^^^^^^^^^^^^^^^^^^^^^^^^^^^^^^^^^^^^^^^^\n",
            "  File \"/usr/local/lib/python3.11/dist-packages/dask/base.py\", line 422, in collections_to_dsk\n",
            "    dsk = opt(dsk, keys, **kwargs)\n",
            "          ^^^^^^^^^^^^^^^^^^^^^^^^\n",
            "  File \"/usr/local/lib/python3.11/dist-packages/dask/array/optimization.py\", line 49, in optimize\n",
            "    dsk = optimize_blockwise(dsk, keys=keys)\n",
            "          ^^^^^^^^^^^^^^^^^^^^^^^^^^^^^^^^^^\n",
            "  File \"/usr/local/lib/python3.11/dist-packages/dask/blockwise.py\", line 1079, in optimize_blockwise\n",
            "    out = _optimize_blockwise(graph, keys=keys)\n",
            "          ^^^^^^^^^^^^^^^^^^^^^^^^^^^^^^^^^^^^^\n",
            "  File \"/usr/local/lib/python3.11/dist-packages/dask/blockwise.py\", line 1171, in _optimize_blockwise\n",
            "    new_deps |= keys_in_tasks(full_graph.dependencies, [k])\n",
            "                ^^^^^^^^^^^^^^^^^^^^^^^^^^^^^^^^^^^^^^^^^^^\n",
            "  File \"/usr/local/lib/python3.11/dist-packages/dask/core.py\", line None, in keys_in_tasks\n",
            "KeyboardInterrupt\n",
            "\n",
            "During handling of the above exception, another exception occurred:\n",
            "\n",
            "Traceback (most recent call last):\n",
            "  File \"/usr/local/lib/python3.11/dist-packages/IPython/core/interactiveshell.py\", line 2099, in showtraceback\n",
            "    stb = value._render_traceback_()\n",
            "          ^^^^^^^^^^^^^^^^^^^^^^^^\n",
            "AttributeError: 'KeyboardInterrupt' object has no attribute '_render_traceback_'\n",
            "\n",
            "During handling of the above exception, another exception occurred:\n",
            "\n",
            "Traceback (most recent call last):\n",
            "  File \"/usr/local/lib/python3.11/dist-packages/IPython/core/ultratb.py\", line 1101, in get_records\n",
            "    return _fixed_getinnerframes(etb, number_of_lines_of_context, tb_offset)\n",
            "           ^^^^^^^^^^^^^^^^^^^^^^^^^^^^^^^^^^^^^^^^^^^^^^^^^^^^^^^^^^^^^^^^^\n",
            "  File \"/usr/local/lib/python3.11/dist-packages/IPython/core/ultratb.py\", line 248, in wrapped\n",
            "    return f(*args, **kwargs)\n",
            "           ^^^^^^^^^^^^^^^^^^\n",
            "  File \"/usr/local/lib/python3.11/dist-packages/IPython/core/ultratb.py\", line 281, in _fixed_getinnerframes\n",
            "    records = fix_frame_records_filenames(inspect.getinnerframes(etb, context))\n",
            "                                          ^^^^^^^^^^^^^^^^^^^^^^^^^^^^^^^^^^^^\n",
            "  File \"/usr/lib/python3.11/inspect.py\", line 1739, in getinnerframes\n",
            "    traceback_info = getframeinfo(tb, context)\n",
            "                     ^^^^^^^^^^^^^^^^^^^^^^^^^\n",
            "  File \"/usr/lib/python3.11/inspect.py\", line 1686, in getframeinfo\n",
            "    start = lineno - 1 - context//2\n",
            "            ~~~~~~~^~~\n",
            "TypeError: unsupported operand type(s) for -: 'NoneType' and 'int'\n",
            "Traceback (most recent call last):\n",
            "  File \"/usr/local/lib/python3.11/dist-packages/IPython/core/interactiveshell.py\", line 3553, in run_code\n",
            "    exec(code_obj, self.user_global_ns, self.user_ns)\n",
            "  File \"<ipython-input-179-de16e834fe6e>\", line 11, in <cell line: 0>\n",
            "    waterht = ax.contourf(water_level.Longitude, water_level.Latitude, water_level.isel(time=l), levels = levels, cmap = cmap_plot)\n",
            "              ^^^^^^^^^^^^^^^^^^^^^^^^^^^^^^^^^^^^^^^^^^^^^^^^^^^^^^^^^^^^^^^^^^^^^^^^^^^^^^^^^^^^^^^^^^^^^^^^^^^^^^^^^^^^^^^^^^^^^\n",
            "  File \"/usr/local/lib/python3.11/dist-packages/cartopy/mpl/geoaxes.py\", line 306, in wrapper\n",
            "    return func(self, *args, **kwargs)\n",
            "           ^^^^^^^^^^^^^^^^^^^^^^^^^^^\n",
            "  File \"/usr/local/lib/python3.11/dist-packages/cartopy/mpl/geoaxes.py\", line 350, in wrapper\n",
            "    return func(self, *args, **kwargs)\n",
            "           ^^^^^^^^^^^^^^^^^^^^^^^^^^^\n",
            "  File \"/usr/local/lib/python3.11/dist-packages/cartopy/mpl/geoaxes.py\", line 1646, in contourf\n",
            "    result = super().contourf(*args, **kwargs)\n",
            "             ^^^^^^^^^^^^^^^^^^^^^^^^^^^^^^^^^\n",
            "  File \"/usr/local/lib/python3.11/dist-packages/matplotlib/__init__.py\", line 1521, in inner\n",
            "    return func(\n",
            "           ^^^^^\n",
            "  File \"/usr/local/lib/python3.11/dist-packages/matplotlib/axes/_axes.py\", line 6760, in contourf\n",
            "    contours = mcontour.QuadContourSet(self, *args, **kwargs)\n",
            "               ^^^^^^^^^^^^^^^^^^^^^^^^^^^^^^^^^^^^^^^^^^^^^^\n",
            "  File \"/usr/local/lib/python3.11/dist-packages/matplotlib/contour.py\", line 708, in __init__\n",
            "    kwargs = self._process_args(*args, **kwargs)\n",
            "             ^^^^^^^^^^^^^^^^^^^^^^^^^^^^^^^^^^^\n",
            "  File \"/usr/local/lib/python3.11/dist-packages/matplotlib/contour.py\", line 1326, in _process_args\n",
            "    x, y, z = self._contour_args(args, kwargs)\n",
            "              ^^^^^^^^^^^^^^^^^^^^^^^^^^^^^^^^\n",
            "  File \"/usr/local/lib/python3.11/dist-packages/matplotlib/contour.py\", line 1366, in _contour_args\n",
            "    x, y, z = self._check_xyz(x, y, z_orig, kwargs)\n",
            "              ^^^^^^^^^^^^^^^^^^^^^^^^^^^^^^^^^^^^^\n",
            "  File \"/usr/local/lib/python3.11/dist-packages/matplotlib/contour.py\", line 1387, in _check_xyz\n",
            "    x = np.asarray(x, dtype=np.float64)\n",
            "        ^^^^^^^^^^^^^^^^^^^^^^^^^^^^^^^\n",
            "  File \"/usr/local/lib/python3.11/dist-packages/xarray/core/common.py\", line 180, in __array__\n",
            "    return np.array(self.values, dtype=dtype, copy=copy)\n",
            "                    ^^^^^^^^^^^\n",
            "  File \"/usr/local/lib/python3.11/dist-packages/xarray/core/dataarray.py\", line 814, in values\n",
            "    return self.variable.values\n",
            "           ^^^^^^^^^^^^^^^^^^^^\n",
            "  File \"/usr/local/lib/python3.11/dist-packages/xarray/core/variable.py\", line 565, in values\n",
            "    return _as_array_or_item(self._data)\n",
            "           ^^^^^^^^^^^^^^^^^^^^^^^^^^^^^\n",
            "  File \"/usr/local/lib/python3.11/dist-packages/xarray/core/variable.py\", line 362, in _as_array_or_item\n",
            "    data = np.asarray(data)\n",
            "           ^^^^^^^^^^^^^^^^\n",
            "  File \"/usr/local/lib/python3.11/dist-packages/dask/array/core.py\", line 1697, in __array__\n",
            "    x = self.compute()\n",
            "        ^^^^^^^^^^^^^^\n",
            "  File \"/usr/local/lib/python3.11/dist-packages/dask/base.py\", line 372, in compute\n",
            "    (result,) = compute(self, traverse=False, **kwargs)\n",
            "                ^^^^^^^^^^^^^^^^^^^^^^^^^^^^^^^^^^^^^^^\n",
            "  File \"/usr/local/lib/python3.11/dist-packages/dask/base.py\", line 653, in compute\n",
            "    dsk = collections_to_dsk(collections, optimize_graph, **kwargs)\n",
            "          ^^^^^^^^^^^^^^^^^^^^^^^^^^^^^^^^^^^^^^^^^^^^^^^^^^^^^^^^^\n",
            "  File \"/usr/local/lib/python3.11/dist-packages/dask/base.py\", line 422, in collections_to_dsk\n",
            "    dsk = opt(dsk, keys, **kwargs)\n",
            "          ^^^^^^^^^^^^^^^^^^^^^^^^\n",
            "  File \"/usr/local/lib/python3.11/dist-packages/dask/array/optimization.py\", line 49, in optimize\n",
            "    dsk = optimize_blockwise(dsk, keys=keys)\n",
            "          ^^^^^^^^^^^^^^^^^^^^^^^^^^^^^^^^^^\n",
            "  File \"/usr/local/lib/python3.11/dist-packages/dask/blockwise.py\", line 1079, in optimize_blockwise\n",
            "    out = _optimize_blockwise(graph, keys=keys)\n",
            "          ^^^^^^^^^^^^^^^^^^^^^^^^^^^^^^^^^^^^^\n",
            "  File \"/usr/local/lib/python3.11/dist-packages/dask/blockwise.py\", line 1171, in _optimize_blockwise\n",
            "    new_deps |= keys_in_tasks(full_graph.dependencies, [k])\n",
            "                ^^^^^^^^^^^^^^^^^^^^^^^^^^^^^^^^^^^^^^^^^^^\n",
            "  File \"/usr/local/lib/python3.11/dist-packages/dask/core.py\", line None, in keys_in_tasks\n",
            "KeyboardInterrupt\n",
            "\n",
            "During handling of the above exception, another exception occurred:\n",
            "\n",
            "Traceback (most recent call last):\n",
            "  File \"/usr/local/lib/python3.11/dist-packages/IPython/core/interactiveshell.py\", line 2099, in showtraceback\n",
            "    stb = value._render_traceback_()\n",
            "          ^^^^^^^^^^^^^^^^^^^^^^^^\n",
            "AttributeError: 'KeyboardInterrupt' object has no attribute '_render_traceback_'\n",
            "\n",
            "During handling of the above exception, another exception occurred:\n",
            "\n",
            "Traceback (most recent call last):\n",
            "  File \"/usr/local/lib/python3.11/dist-packages/IPython/core/interactiveshell.py\", line 3473, in run_ast_nodes\n",
            "    if (await self.run_code(code, result,  async_=asy)):\n",
            "        ^^^^^^^^^^^^^^^^^^^^^^^^^^^^^^^^^^^^^^^^^^^^^^\n",
            "  File \"/usr/local/lib/python3.11/dist-packages/IPython/core/interactiveshell.py\", line 3575, in run_code\n",
            "    self.showtraceback(running_compiled_code=True)\n",
            "  File \"/usr/local/lib/python3.11/dist-packages/IPython/core/interactiveshell.py\", line 2101, in showtraceback\n",
            "    stb = self.InteractiveTB.structured_traceback(etype,\n",
            "          ^^^^^^^^^^^^^^^^^^^^^^^^^^^^^^^^^^^^^^^^^^^^^^\n",
            "  File \"/usr/local/lib/python3.11/dist-packages/IPython/core/ultratb.py\", line 1367, in structured_traceback\n",
            "    return FormattedTB.structured_traceback(\n",
            "           ^^^^^^^^^^^^^^^^^^^^^^^^^^^^^^^^^\n",
            "  File \"/usr/local/lib/python3.11/dist-packages/IPython/core/ultratb.py\", line 1267, in structured_traceback\n",
            "    return VerboseTB.structured_traceback(\n",
            "           ^^^^^^^^^^^^^^^^^^^^^^^^^^^^^^^\n",
            "  File \"/usr/local/lib/python3.11/dist-packages/IPython/core/ultratb.py\", line 1124, in structured_traceback\n",
            "    formatted_exception = self.format_exception_as_a_whole(etype, evalue, etb, number_of_lines_of_context,\n",
            "                          ^^^^^^^^^^^^^^^^^^^^^^^^^^^^^^^^^^^^^^^^^^^^^^^^^^^^^^^^^^^^^^^^^^^^^^^^^^^^^^^^\n",
            "  File \"/usr/local/lib/python3.11/dist-packages/IPython/core/ultratb.py\", line 1082, in format_exception_as_a_whole\n",
            "    last_unique, recursion_repeat = find_recursion(orig_etype, evalue, records)\n",
            "                                    ^^^^^^^^^^^^^^^^^^^^^^^^^^^^^^^^^^^^^^^^^^^\n",
            "  File \"/usr/local/lib/python3.11/dist-packages/IPython/core/ultratb.py\", line 382, in find_recursion\n",
            "    return len(records), 0\n",
            "           ^^^^^^^^^^^^\n",
            "TypeError: object of type 'NoneType' has no len()\n",
            "\n",
            "During handling of the above exception, another exception occurred:\n",
            "\n",
            "Traceback (most recent call last):\n",
            "  File \"/usr/local/lib/python3.11/dist-packages/IPython/core/interactiveshell.py\", line 2099, in showtraceback\n",
            "    stb = value._render_traceback_()\n",
            "          ^^^^^^^^^^^^^^^^^^^^^^^^\n",
            "AttributeError: 'TypeError' object has no attribute '_render_traceback_'\n",
            "\n",
            "During handling of the above exception, another exception occurred:\n",
            "\n",
            "Traceback (most recent call last):\n",
            "  File \"/usr/local/lib/python3.11/dist-packages/IPython/core/ultratb.py\", line 1101, in get_records\n",
            "    return _fixed_getinnerframes(etb, number_of_lines_of_context, tb_offset)\n",
            "           ^^^^^^^^^^^^^^^^^^^^^^^^^^^^^^^^^^^^^^^^^^^^^^^^^^^^^^^^^^^^^^^^^\n",
            "  File \"/usr/local/lib/python3.11/dist-packages/IPython/core/ultratb.py\", line 248, in wrapped\n",
            "    return f(*args, **kwargs)\n",
            "           ^^^^^^^^^^^^^^^^^^\n",
            "  File \"/usr/local/lib/python3.11/dist-packages/IPython/core/ultratb.py\", line 281, in _fixed_getinnerframes\n",
            "    records = fix_frame_records_filenames(inspect.getinnerframes(etb, context))\n",
            "                                          ^^^^^^^^^^^^^^^^^^^^^^^^^^^^^^^^^^^^\n",
            "  File \"/usr/lib/python3.11/inspect.py\", line 1739, in getinnerframes\n",
            "    traceback_info = getframeinfo(tb, context)\n",
            "                     ^^^^^^^^^^^^^^^^^^^^^^^^^\n",
            "  File \"/usr/lib/python3.11/inspect.py\", line 1686, in getframeinfo\n",
            "    start = lineno - 1 - context//2\n",
            "            ~~~~~~~^~~\n",
            "TypeError: unsupported operand type(s) for -: 'NoneType' and 'int'\n",
            "Traceback (most recent call last):\n",
            "  File \"/usr/local/lib/python3.11/dist-packages/IPython/core/interactiveshell.py\", line 3553, in run_code\n",
            "    exec(code_obj, self.user_global_ns, self.user_ns)\n",
            "  File \"<ipython-input-179-de16e834fe6e>\", line 11, in <cell line: 0>\n",
            "    waterht = ax.contourf(water_level.Longitude, water_level.Latitude, water_level.isel(time=l), levels = levels, cmap = cmap_plot)\n",
            "              ^^^^^^^^^^^^^^^^^^^^^^^^^^^^^^^^^^^^^^^^^^^^^^^^^^^^^^^^^^^^^^^^^^^^^^^^^^^^^^^^^^^^^^^^^^^^^^^^^^^^^^^^^^^^^^^^^^^^^\n",
            "  File \"/usr/local/lib/python3.11/dist-packages/cartopy/mpl/geoaxes.py\", line 306, in wrapper\n",
            "    return func(self, *args, **kwargs)\n",
            "           ^^^^^^^^^^^^^^^^^^^^^^^^^^^\n",
            "  File \"/usr/local/lib/python3.11/dist-packages/cartopy/mpl/geoaxes.py\", line 350, in wrapper\n",
            "    return func(self, *args, **kwargs)\n",
            "           ^^^^^^^^^^^^^^^^^^^^^^^^^^^\n",
            "  File \"/usr/local/lib/python3.11/dist-packages/cartopy/mpl/geoaxes.py\", line 1646, in contourf\n",
            "    result = super().contourf(*args, **kwargs)\n",
            "             ^^^^^^^^^^^^^^^^^^^^^^^^^^^^^^^^^\n",
            "  File \"/usr/local/lib/python3.11/dist-packages/matplotlib/__init__.py\", line 1521, in inner\n",
            "    return func(\n",
            "           ^^^^^\n",
            "  File \"/usr/local/lib/python3.11/dist-packages/matplotlib/axes/_axes.py\", line 6760, in contourf\n",
            "    contours = mcontour.QuadContourSet(self, *args, **kwargs)\n",
            "               ^^^^^^^^^^^^^^^^^^^^^^^^^^^^^^^^^^^^^^^^^^^^^^\n",
            "  File \"/usr/local/lib/python3.11/dist-packages/matplotlib/contour.py\", line 708, in __init__\n",
            "    kwargs = self._process_args(*args, **kwargs)\n",
            "             ^^^^^^^^^^^^^^^^^^^^^^^^^^^^^^^^^^^\n",
            "  File \"/usr/local/lib/python3.11/dist-packages/matplotlib/contour.py\", line 1326, in _process_args\n",
            "    x, y, z = self._contour_args(args, kwargs)\n",
            "              ^^^^^^^^^^^^^^^^^^^^^^^^^^^^^^^^\n",
            "  File \"/usr/local/lib/python3.11/dist-packages/matplotlib/contour.py\", line 1366, in _contour_args\n",
            "    x, y, z = self._check_xyz(x, y, z_orig, kwargs)\n",
            "              ^^^^^^^^^^^^^^^^^^^^^^^^^^^^^^^^^^^^^\n",
            "  File \"/usr/local/lib/python3.11/dist-packages/matplotlib/contour.py\", line 1387, in _check_xyz\n",
            "    x = np.asarray(x, dtype=np.float64)\n",
            "        ^^^^^^^^^^^^^^^^^^^^^^^^^^^^^^^\n",
            "  File \"/usr/local/lib/python3.11/dist-packages/xarray/core/common.py\", line 180, in __array__\n",
            "    return np.array(self.values, dtype=dtype, copy=copy)\n",
            "                    ^^^^^^^^^^^\n",
            "  File \"/usr/local/lib/python3.11/dist-packages/xarray/core/dataarray.py\", line 814, in values\n",
            "    return self.variable.values\n",
            "           ^^^^^^^^^^^^^^^^^^^^\n",
            "  File \"/usr/local/lib/python3.11/dist-packages/xarray/core/variable.py\", line 565, in values\n",
            "    return _as_array_or_item(self._data)\n",
            "           ^^^^^^^^^^^^^^^^^^^^^^^^^^^^^\n",
            "  File \"/usr/local/lib/python3.11/dist-packages/xarray/core/variable.py\", line 362, in _as_array_or_item\n",
            "    data = np.asarray(data)\n",
            "           ^^^^^^^^^^^^^^^^\n",
            "  File \"/usr/local/lib/python3.11/dist-packages/dask/array/core.py\", line 1697, in __array__\n",
            "    x = self.compute()\n",
            "        ^^^^^^^^^^^^^^\n",
            "  File \"/usr/local/lib/python3.11/dist-packages/dask/base.py\", line 372, in compute\n",
            "    (result,) = compute(self, traverse=False, **kwargs)\n",
            "                ^^^^^^^^^^^^^^^^^^^^^^^^^^^^^^^^^^^^^^^\n",
            "  File \"/usr/local/lib/python3.11/dist-packages/dask/base.py\", line 653, in compute\n",
            "    dsk = collections_to_dsk(collections, optimize_graph, **kwargs)\n",
            "          ^^^^^^^^^^^^^^^^^^^^^^^^^^^^^^^^^^^^^^^^^^^^^^^^^^^^^^^^^\n",
            "  File \"/usr/local/lib/python3.11/dist-packages/dask/base.py\", line 422, in collections_to_dsk\n",
            "    dsk = opt(dsk, keys, **kwargs)\n",
            "          ^^^^^^^^^^^^^^^^^^^^^^^^\n",
            "  File \"/usr/local/lib/python3.11/dist-packages/dask/array/optimization.py\", line 49, in optimize\n",
            "    dsk = optimize_blockwise(dsk, keys=keys)\n",
            "          ^^^^^^^^^^^^^^^^^^^^^^^^^^^^^^^^^^\n",
            "  File \"/usr/local/lib/python3.11/dist-packages/dask/blockwise.py\", line 1079, in optimize_blockwise\n",
            "    out = _optimize_blockwise(graph, keys=keys)\n",
            "          ^^^^^^^^^^^^^^^^^^^^^^^^^^^^^^^^^^^^^\n",
            "  File \"/usr/local/lib/python3.11/dist-packages/dask/blockwise.py\", line 1171, in _optimize_blockwise\n",
            "    new_deps |= keys_in_tasks(full_graph.dependencies, [k])\n",
            "                ^^^^^^^^^^^^^^^^^^^^^^^^^^^^^^^^^^^^^^^^^^^\n",
            "  File \"/usr/local/lib/python3.11/dist-packages/dask/core.py\", line None, in keys_in_tasks\n",
            "KeyboardInterrupt\n",
            "\n",
            "During handling of the above exception, another exception occurred:\n",
            "\n",
            "Traceback (most recent call last):\n",
            "  File \"/usr/local/lib/python3.11/dist-packages/IPython/core/interactiveshell.py\", line 2099, in showtraceback\n",
            "    stb = value._render_traceback_()\n",
            "          ^^^^^^^^^^^^^^^^^^^^^^^^\n",
            "AttributeError: 'KeyboardInterrupt' object has no attribute '_render_traceback_'\n",
            "\n",
            "During handling of the above exception, another exception occurred:\n",
            "\n",
            "Traceback (most recent call last):\n",
            "  File \"/usr/local/lib/python3.11/dist-packages/IPython/core/interactiveshell.py\", line 3473, in run_ast_nodes\n",
            "    if (await self.run_code(code, result,  async_=asy)):\n",
            "        ^^^^^^^^^^^^^^^^^^^^^^^^^^^^^^^^^^^^^^^^^^^^^^\n",
            "  File \"/usr/local/lib/python3.11/dist-packages/IPython/core/interactiveshell.py\", line 3575, in run_code\n",
            "    self.showtraceback(running_compiled_code=True)\n",
            "  File \"/usr/local/lib/python3.11/dist-packages/IPython/core/interactiveshell.py\", line 2101, in showtraceback\n",
            "    stb = self.InteractiveTB.structured_traceback(etype,\n",
            "          ^^^^^^^^^^^^^^^^^^^^^^^^^^^^^^^^^^^^^^^^^^^^^^\n",
            "  File \"/usr/local/lib/python3.11/dist-packages/IPython/core/ultratb.py\", line 1367, in structured_traceback\n",
            "    return FormattedTB.structured_traceback(\n",
            "           ^^^^^^^^^^^^^^^^^^^^^^^^^^^^^^^^^\n",
            "  File \"/usr/local/lib/python3.11/dist-packages/IPython/core/ultratb.py\", line 1267, in structured_traceback\n",
            "    return VerboseTB.structured_traceback(\n",
            "           ^^^^^^^^^^^^^^^^^^^^^^^^^^^^^^^\n",
            "  File \"/usr/local/lib/python3.11/dist-packages/IPython/core/ultratb.py\", line 1124, in structured_traceback\n",
            "    formatted_exception = self.format_exception_as_a_whole(etype, evalue, etb, number_of_lines_of_context,\n",
            "                          ^^^^^^^^^^^^^^^^^^^^^^^^^^^^^^^^^^^^^^^^^^^^^^^^^^^^^^^^^^^^^^^^^^^^^^^^^^^^^^^^\n",
            "  File \"/usr/local/lib/python3.11/dist-packages/IPython/core/ultratb.py\", line 1082, in format_exception_as_a_whole\n",
            "    last_unique, recursion_repeat = find_recursion(orig_etype, evalue, records)\n",
            "                                    ^^^^^^^^^^^^^^^^^^^^^^^^^^^^^^^^^^^^^^^^^^^\n",
            "  File \"/usr/local/lib/python3.11/dist-packages/IPython/core/ultratb.py\", line 382, in find_recursion\n",
            "    return len(records), 0\n",
            "           ^^^^^^^^^^^^\n",
            "TypeError: object of type 'NoneType' has no len()\n",
            "\n",
            "During handling of the above exception, another exception occurred:\n",
            "\n",
            "Traceback (most recent call last):\n",
            "  File \"/usr/local/lib/python3.11/dist-packages/IPython/core/interactiveshell.py\", line 2099, in showtraceback\n",
            "    stb = value._render_traceback_()\n",
            "          ^^^^^^^^^^^^^^^^^^^^^^^^\n",
            "AttributeError: 'TypeError' object has no attribute '_render_traceback_'\n",
            "\n",
            "During handling of the above exception, another exception occurred:\n",
            "\n",
            "Traceback (most recent call last):\n",
            "  File \"/usr/local/lib/python3.11/dist-packages/IPython/core/interactiveshell.py\", line 3030, in _run_cell\n",
            "    return runner(coro)\n",
            "           ^^^^^^^^^^^^\n",
            "  File \"/usr/local/lib/python3.11/dist-packages/IPython/core/async_helpers.py\", line 78, in _pseudo_sync_runner\n",
            "    coro.send(None)\n",
            "  File \"/usr/local/lib/python3.11/dist-packages/IPython/core/interactiveshell.py\", line 3257, in run_cell_async\n",
            "    has_raised = await self.run_ast_nodes(code_ast.body, cell_name,\n",
            "                 ^^^^^^^^^^^^^^^^^^^^^^^^^^^^^^^^^^^^^^^^^^^^^^^^^^\n",
            "  File \"/usr/local/lib/python3.11/dist-packages/IPython/core/interactiveshell.py\", line 3492, in run_ast_nodes\n",
            "    self.showtraceback()\n",
            "  File \"/usr/local/lib/python3.11/dist-packages/IPython/core/interactiveshell.py\", line 2101, in showtraceback\n",
            "    stb = self.InteractiveTB.structured_traceback(etype,\n",
            "          ^^^^^^^^^^^^^^^^^^^^^^^^^^^^^^^^^^^^^^^^^^^^^^\n",
            "  File \"/usr/local/lib/python3.11/dist-packages/IPython/core/ultratb.py\", line 1367, in structured_traceback\n",
            "    return FormattedTB.structured_traceback(\n",
            "           ^^^^^^^^^^^^^^^^^^^^^^^^^^^^^^^^^\n",
            "  File \"/usr/local/lib/python3.11/dist-packages/IPython/core/ultratb.py\", line 1267, in structured_traceback\n",
            "    return VerboseTB.structured_traceback(\n",
            "           ^^^^^^^^^^^^^^^^^^^^^^^^^^^^^^^\n",
            "  File \"/usr/local/lib/python3.11/dist-packages/IPython/core/ultratb.py\", line 1142, in structured_traceback\n",
            "    formatted_exceptions += self.format_exception_as_a_whole(etype, evalue, etb, lines_of_context,\n",
            "                            ^^^^^^^^^^^^^^^^^^^^^^^^^^^^^^^^^^^^^^^^^^^^^^^^^^^^^^^^^^^^^^^^^^^^^^\n",
            "  File \"/usr/local/lib/python3.11/dist-packages/IPython/core/ultratb.py\", line 1082, in format_exception_as_a_whole\n",
            "    last_unique, recursion_repeat = find_recursion(orig_etype, evalue, records)\n",
            "                                    ^^^^^^^^^^^^^^^^^^^^^^^^^^^^^^^^^^^^^^^^^^^\n",
            "  File \"/usr/local/lib/python3.11/dist-packages/IPython/core/ultratb.py\", line 382, in find_recursion\n",
            "    return len(records), 0\n",
            "           ^^^^^^^^^^^^\n",
            "TypeError: object of type 'NoneType' has no len()\n",
            "\n",
            "During handling of the above exception, another exception occurred:\n",
            "\n",
            "Traceback (most recent call last):\n",
            "  File \"/usr/local/lib/python3.11/dist-packages/IPython/core/interactiveshell.py\", line 2099, in showtraceback\n",
            "    stb = value._render_traceback_()\n",
            "          ^^^^^^^^^^^^^^^^^^^^^^^^\n",
            "AttributeError: 'TypeError' object has no attribute '_render_traceback_'\n",
            "\n",
            "During handling of the above exception, another exception occurred:\n",
            "\n",
            "Traceback (most recent call last):\n",
            "  File \"/usr/local/lib/python3.11/dist-packages/IPython/core/ultratb.py\", line 1101, in get_records\n",
            "    return _fixed_getinnerframes(etb, number_of_lines_of_context, tb_offset)\n",
            "           ^^^^^^^^^^^^^^^^^^^^^^^^^^^^^^^^^^^^^^^^^^^^^^^^^^^^^^^^^^^^^^^^^\n",
            "  File \"/usr/local/lib/python3.11/dist-packages/IPython/core/ultratb.py\", line 248, in wrapped\n",
            "    return f(*args, **kwargs)\n",
            "           ^^^^^^^^^^^^^^^^^^\n",
            "  File \"/usr/local/lib/python3.11/dist-packages/IPython/core/ultratb.py\", line 281, in _fixed_getinnerframes\n",
            "    records = fix_frame_records_filenames(inspect.getinnerframes(etb, context))\n",
            "                                          ^^^^^^^^^^^^^^^^^^^^^^^^^^^^^^^^^^^^\n",
            "  File \"/usr/lib/python3.11/inspect.py\", line 1739, in getinnerframes\n",
            "    traceback_info = getframeinfo(tb, context)\n",
            "                     ^^^^^^^^^^^^^^^^^^^^^^^^^\n",
            "  File \"/usr/lib/python3.11/inspect.py\", line 1686, in getframeinfo\n",
            "    start = lineno - 1 - context//2\n",
            "            ~~~~~~~^~~\n",
            "TypeError: unsupported operand type(s) for -: 'NoneType' and 'int'\n"
          ]
        },
        {
          "output_type": "stream",
          "name": "stderr",
          "text": [
            "ERROR:root:Internal Python error in the inspect module.\n",
            "Below is the traceback from this internal error.\n",
            "\n"
          ]
        },
        {
          "output_type": "stream",
          "name": "stdout",
          "text": [
            "Error in callback <function flush_figures at 0x799d5ecb82c0> (for post_execute):\n",
            "Traceback (most recent call last):\n",
            "  File \"/usr/local/lib/python3.11/dist-packages/IPython/core/interactiveshell.py\", line 3553, in run_code\n",
            "    exec(code_obj, self.user_global_ns, self.user_ns)\n",
            "  File \"<ipython-input-179-de16e834fe6e>\", line 11, in <cell line: 0>\n",
            "    waterht = ax.contourf(water_level.Longitude, water_level.Latitude, water_level.isel(time=l), levels = levels, cmap = cmap_plot)\n",
            "              ^^^^^^^^^^^^^^^^^^^^^^^^^^^^^^^^^^^^^^^^^^^^^^^^^^^^^^^^^^^^^^^^^^^^^^^^^^^^^^^^^^^^^^^^^^^^^^^^^^^^^^^^^^^^^^^^^^^^^\n",
            "  File \"/usr/local/lib/python3.11/dist-packages/cartopy/mpl/geoaxes.py\", line 306, in wrapper\n",
            "    return func(self, *args, **kwargs)\n",
            "           ^^^^^^^^^^^^^^^^^^^^^^^^^^^\n",
            "  File \"/usr/local/lib/python3.11/dist-packages/cartopy/mpl/geoaxes.py\", line 350, in wrapper\n",
            "    return func(self, *args, **kwargs)\n",
            "           ^^^^^^^^^^^^^^^^^^^^^^^^^^^\n",
            "  File \"/usr/local/lib/python3.11/dist-packages/cartopy/mpl/geoaxes.py\", line 1646, in contourf\n",
            "    result = super().contourf(*args, **kwargs)\n",
            "             ^^^^^^^^^^^^^^^^^^^^^^^^^^^^^^^^^\n",
            "  File \"/usr/local/lib/python3.11/dist-packages/matplotlib/__init__.py\", line 1521, in inner\n",
            "    return func(\n",
            "           ^^^^^\n",
            "  File \"/usr/local/lib/python3.11/dist-packages/matplotlib/axes/_axes.py\", line 6760, in contourf\n",
            "    contours = mcontour.QuadContourSet(self, *args, **kwargs)\n",
            "               ^^^^^^^^^^^^^^^^^^^^^^^^^^^^^^^^^^^^^^^^^^^^^^\n",
            "  File \"/usr/local/lib/python3.11/dist-packages/matplotlib/contour.py\", line 708, in __init__\n",
            "    kwargs = self._process_args(*args, **kwargs)\n",
            "             ^^^^^^^^^^^^^^^^^^^^^^^^^^^^^^^^^^^\n",
            "  File \"/usr/local/lib/python3.11/dist-packages/matplotlib/contour.py\", line 1326, in _process_args\n",
            "    x, y, z = self._contour_args(args, kwargs)\n",
            "              ^^^^^^^^^^^^^^^^^^^^^^^^^^^^^^^^\n",
            "  File \"/usr/local/lib/python3.11/dist-packages/matplotlib/contour.py\", line 1366, in _contour_args\n",
            "    x, y, z = self._check_xyz(x, y, z_orig, kwargs)\n",
            "              ^^^^^^^^^^^^^^^^^^^^^^^^^^^^^^^^^^^^^\n",
            "  File \"/usr/local/lib/python3.11/dist-packages/matplotlib/contour.py\", line 1387, in _check_xyz\n",
            "    x = np.asarray(x, dtype=np.float64)\n",
            "        ^^^^^^^^^^^^^^^^^^^^^^^^^^^^^^^\n",
            "  File \"/usr/local/lib/python3.11/dist-packages/xarray/core/common.py\", line 180, in __array__\n",
            "    return np.array(self.values, dtype=dtype, copy=copy)\n",
            "                    ^^^^^^^^^^^\n",
            "  File \"/usr/local/lib/python3.11/dist-packages/xarray/core/dataarray.py\", line 814, in values\n",
            "    return self.variable.values\n",
            "           ^^^^^^^^^^^^^^^^^^^^\n",
            "  File \"/usr/local/lib/python3.11/dist-packages/xarray/core/variable.py\", line 565, in values\n",
            "    return _as_array_or_item(self._data)\n",
            "           ^^^^^^^^^^^^^^^^^^^^^^^^^^^^^\n",
            "  File \"/usr/local/lib/python3.11/dist-packages/xarray/core/variable.py\", line 362, in _as_array_or_item\n",
            "    data = np.asarray(data)\n",
            "           ^^^^^^^^^^^^^^^^\n",
            "  File \"/usr/local/lib/python3.11/dist-packages/dask/array/core.py\", line 1697, in __array__\n",
            "    x = self.compute()\n",
            "        ^^^^^^^^^^^^^^\n",
            "  File \"/usr/local/lib/python3.11/dist-packages/dask/base.py\", line 372, in compute\n",
            "    (result,) = compute(self, traverse=False, **kwargs)\n",
            "                ^^^^^^^^^^^^^^^^^^^^^^^^^^^^^^^^^^^^^^^\n",
            "  File \"/usr/local/lib/python3.11/dist-packages/dask/base.py\", line 653, in compute\n",
            "    dsk = collections_to_dsk(collections, optimize_graph, **kwargs)\n",
            "          ^^^^^^^^^^^^^^^^^^^^^^^^^^^^^^^^^^^^^^^^^^^^^^^^^^^^^^^^^\n",
            "  File \"/usr/local/lib/python3.11/dist-packages/dask/base.py\", line 422, in collections_to_dsk\n",
            "    dsk = opt(dsk, keys, **kwargs)\n",
            "          ^^^^^^^^^^^^^^^^^^^^^^^^\n",
            "  File \"/usr/local/lib/python3.11/dist-packages/dask/array/optimization.py\", line 49, in optimize\n",
            "    dsk = optimize_blockwise(dsk, keys=keys)\n",
            "          ^^^^^^^^^^^^^^^^^^^^^^^^^^^^^^^^^^\n",
            "  File \"/usr/local/lib/python3.11/dist-packages/dask/blockwise.py\", line 1079, in optimize_blockwise\n",
            "    out = _optimize_blockwise(graph, keys=keys)\n",
            "          ^^^^^^^^^^^^^^^^^^^^^^^^^^^^^^^^^^^^^\n",
            "  File \"/usr/local/lib/python3.11/dist-packages/dask/blockwise.py\", line 1171, in _optimize_blockwise\n",
            "    new_deps |= keys_in_tasks(full_graph.dependencies, [k])\n",
            "                ^^^^^^^^^^^^^^^^^^^^^^^^^^^^^^^^^^^^^^^^^^^\n",
            "  File \"/usr/local/lib/python3.11/dist-packages/dask/core.py\", line None, in keys_in_tasks\n",
            "KeyboardInterrupt\n",
            "\n",
            "During handling of the above exception, another exception occurred:\n",
            "\n",
            "Traceback (most recent call last):\n",
            "  File \"/usr/local/lib/python3.11/dist-packages/IPython/core/interactiveshell.py\", line 2099, in showtraceback\n",
            "    stb = value._render_traceback_()\n",
            "          ^^^^^^^^^^^^^^^^^^^^^^^^\n",
            "AttributeError: 'KeyboardInterrupt' object has no attribute '_render_traceback_'\n",
            "\n",
            "During handling of the above exception, another exception occurred:\n",
            "\n",
            "Traceback (most recent call last):\n",
            "  File \"/usr/local/lib/python3.11/dist-packages/IPython/core/interactiveshell.py\", line 3473, in run_ast_nodes\n",
            "    if (await self.run_code(code, result,  async_=asy)):\n",
            "        ^^^^^^^^^^^^^^^^^^^^^^^^^^^^^^^^^^^^^^^^^^^^^^\n",
            "  File \"/usr/local/lib/python3.11/dist-packages/IPython/core/interactiveshell.py\", line 3575, in run_code\n",
            "    self.showtraceback(running_compiled_code=True)\n",
            "  File \"/usr/local/lib/python3.11/dist-packages/IPython/core/interactiveshell.py\", line 2101, in showtraceback\n",
            "    stb = self.InteractiveTB.structured_traceback(etype,\n",
            "          ^^^^^^^^^^^^^^^^^^^^^^^^^^^^^^^^^^^^^^^^^^^^^^\n",
            "  File \"/usr/local/lib/python3.11/dist-packages/IPython/core/ultratb.py\", line 1367, in structured_traceback\n",
            "    return FormattedTB.structured_traceback(\n",
            "           ^^^^^^^^^^^^^^^^^^^^^^^^^^^^^^^^^\n",
            "  File \"/usr/local/lib/python3.11/dist-packages/IPython/core/ultratb.py\", line 1267, in structured_traceback\n",
            "    return VerboseTB.structured_traceback(\n",
            "           ^^^^^^^^^^^^^^^^^^^^^^^^^^^^^^^\n",
            "  File \"/usr/local/lib/python3.11/dist-packages/IPython/core/ultratb.py\", line 1124, in structured_traceback\n",
            "    formatted_exception = self.format_exception_as_a_whole(etype, evalue, etb, number_of_lines_of_context,\n",
            "                          ^^^^^^^^^^^^^^^^^^^^^^^^^^^^^^^^^^^^^^^^^^^^^^^^^^^^^^^^^^^^^^^^^^^^^^^^^^^^^^^^\n",
            "  File \"/usr/local/lib/python3.11/dist-packages/IPython/core/ultratb.py\", line 1082, in format_exception_as_a_whole\n",
            "    last_unique, recursion_repeat = find_recursion(orig_etype, evalue, records)\n",
            "                                    ^^^^^^^^^^^^^^^^^^^^^^^^^^^^^^^^^^^^^^^^^^^\n",
            "  File \"/usr/local/lib/python3.11/dist-packages/IPython/core/ultratb.py\", line 382, in find_recursion\n",
            "    return len(records), 0\n",
            "           ^^^^^^^^^^^^\n",
            "TypeError: object of type 'NoneType' has no len()\n",
            "\n",
            "During handling of the above exception, another exception occurred:\n",
            "\n",
            "Traceback (most recent call last):\n",
            "  File \"/usr/local/lib/python3.11/dist-packages/IPython/core/interactiveshell.py\", line 2099, in showtraceback\n",
            "    stb = value._render_traceback_()\n",
            "          ^^^^^^^^^^^^^^^^^^^^^^^^\n",
            "AttributeError: 'TypeError' object has no attribute '_render_traceback_'\n",
            "\n",
            "During handling of the above exception, another exception occurred:\n",
            "\n",
            "Traceback (most recent call last):\n",
            "  File \"/usr/local/lib/python3.11/dist-packages/IPython/core/interactiveshell.py\", line 3030, in _run_cell\n",
            "    return runner(coro)\n",
            "           ^^^^^^^^^^^^\n",
            "  File \"/usr/local/lib/python3.11/dist-packages/IPython/core/async_helpers.py\", line 78, in _pseudo_sync_runner\n",
            "    coro.send(None)\n",
            "  File \"/usr/local/lib/python3.11/dist-packages/IPython/core/interactiveshell.py\", line 3257, in run_cell_async\n",
            "    has_raised = await self.run_ast_nodes(code_ast.body, cell_name,\n",
            "                 ^^^^^^^^^^^^^^^^^^^^^^^^^^^^^^^^^^^^^^^^^^^^^^^^^^\n",
            "  File \"/usr/local/lib/python3.11/dist-packages/IPython/core/interactiveshell.py\", line 3492, in run_ast_nodes\n",
            "    self.showtraceback()\n",
            "  File \"/usr/local/lib/python3.11/dist-packages/IPython/core/interactiveshell.py\", line 2101, in showtraceback\n",
            "    stb = self.InteractiveTB.structured_traceback(etype,\n",
            "          ^^^^^^^^^^^^^^^^^^^^^^^^^^^^^^^^^^^^^^^^^^^^^^\n",
            "  File \"/usr/local/lib/python3.11/dist-packages/IPython/core/ultratb.py\", line 1367, in structured_traceback\n",
            "    return FormattedTB.structured_traceback(\n",
            "           ^^^^^^^^^^^^^^^^^^^^^^^^^^^^^^^^^\n",
            "  File \"/usr/local/lib/python3.11/dist-packages/IPython/core/ultratb.py\", line 1267, in structured_traceback\n",
            "    return VerboseTB.structured_traceback(\n",
            "           ^^^^^^^^^^^^^^^^^^^^^^^^^^^^^^^\n",
            "  File \"/usr/local/lib/python3.11/dist-packages/IPython/core/ultratb.py\", line 1142, in structured_traceback\n",
            "    formatted_exceptions += self.format_exception_as_a_whole(etype, evalue, etb, lines_of_context,\n",
            "                            ^^^^^^^^^^^^^^^^^^^^^^^^^^^^^^^^^^^^^^^^^^^^^^^^^^^^^^^^^^^^^^^^^^^^^^\n",
            "  File \"/usr/local/lib/python3.11/dist-packages/IPython/core/ultratb.py\", line 1082, in format_exception_as_a_whole\n",
            "    last_unique, recursion_repeat = find_recursion(orig_etype, evalue, records)\n",
            "                                    ^^^^^^^^^^^^^^^^^^^^^^^^^^^^^^^^^^^^^^^^^^^\n",
            "  File \"/usr/local/lib/python3.11/dist-packages/IPython/core/ultratb.py\", line 382, in find_recursion\n",
            "    return len(records), 0\n",
            "           ^^^^^^^^^^^^\n",
            "TypeError: object of type 'NoneType' has no len()\n",
            "\n",
            "During handling of the above exception, another exception occurred:\n",
            "\n",
            "Traceback (most recent call last):\n",
            "  File \"/usr/local/lib/python3.11/dist-packages/IPython/core/interactiveshell.py\", line 2099, in showtraceback\n",
            "    stb = value._render_traceback_()\n",
            "          ^^^^^^^^^^^^^^^^^^^^^^^^\n",
            "AttributeError: 'TypeError' object has no attribute '_render_traceback_'\n",
            "\n",
            "During handling of the above exception, another exception occurred:\n",
            "\n",
            "Traceback (most recent call last):\n",
            "  File \"/usr/local/lib/python3.11/dist-packages/IPython/core/interactiveshell.py\", line 2975, in run_cell\n",
            "    result = self._run_cell(\n",
            "             ^^^^^^^^^^^^^^^\n",
            "  File \"/usr/local/lib/python3.11/dist-packages/IPython/core/interactiveshell.py\", line 3037, in _run_cell\n",
            "    self.showtraceback(running_compiled_code=True)\n",
            "  File \"/usr/local/lib/python3.11/dist-packages/IPython/core/interactiveshell.py\", line 2101, in showtraceback\n",
            "    stb = self.InteractiveTB.structured_traceback(etype,\n",
            "          ^^^^^^^^^^^^^^^^^^^^^^^^^^^^^^^^^^^^^^^^^^^^^^\n",
            "  File \"/usr/local/lib/python3.11/dist-packages/IPython/core/ultratb.py\", line 1367, in structured_traceback\n",
            "    return FormattedTB.structured_traceback(\n",
            "           ^^^^^^^^^^^^^^^^^^^^^^^^^^^^^^^^^\n",
            "  File \"/usr/local/lib/python3.11/dist-packages/IPython/core/ultratb.py\", line 1267, in structured_traceback\n",
            "    return VerboseTB.structured_traceback(\n",
            "           ^^^^^^^^^^^^^^^^^^^^^^^^^^^^^^^\n",
            "  File \"/usr/local/lib/python3.11/dist-packages/IPython/core/ultratb.py\", line 1142, in structured_traceback\n",
            "    formatted_exceptions += self.format_exception_as_a_whole(etype, evalue, etb, lines_of_context,\n",
            "                            ^^^^^^^^^^^^^^^^^^^^^^^^^^^^^^^^^^^^^^^^^^^^^^^^^^^^^^^^^^^^^^^^^^^^^^\n",
            "  File \"/usr/local/lib/python3.11/dist-packages/IPython/core/ultratb.py\", line 1082, in format_exception_as_a_whole\n",
            "    last_unique, recursion_repeat = find_recursion(orig_etype, evalue, records)\n",
            "                                    ^^^^^^^^^^^^^^^^^^^^^^^^^^^^^^^^^^^^^^^^^^^\n",
            "  File \"/usr/local/lib/python3.11/dist-packages/IPython/core/ultratb.py\", line 382, in find_recursion\n",
            "    return len(records), 0\n",
            "           ^^^^^^^^^^^^\n",
            "TypeError: object of type 'NoneType' has no len()\n",
            "\n",
            "During handling of the above exception, another exception occurred:\n",
            "\n",
            "Traceback (most recent call last):\n",
            "  File \"/usr/local/lib/python3.11/dist-packages/IPython/core/events.py\", line 89, in trigger\n",
            "    func(*args, **kwargs)\n",
            "  File \"/usr/local/lib/python3.11/dist-packages/matplotlib_inline/backend_inline.py\", line 126, in flush_figures\n",
            "    return show(True)\n",
            "           ^^^^^^^^^^\n",
            "  File \"/usr/local/lib/python3.11/dist-packages/matplotlib_inline/backend_inline.py\", line 90, in show\n",
            "    display(\n",
            "  File \"/usr/local/lib/python3.11/dist-packages/IPython/core/display.py\", line 320, in display\n",
            "    format_dict, md_dict = format(obj, include=include, exclude=exclude)\n",
            "                           ^^^^^^^^^^^^^^^^^^^^^^^^^^^^^^^^^^^^^^^^^^^^^\n",
            "  File \"/usr/local/lib/python3.11/dist-packages/IPython/core/formatters.py\", line 180, in format\n",
            "    data = formatter(obj)\n",
            "           ^^^^^^^^^^^^^^\n",
            "  File \"<decorator-gen-2>\", line 2, in __call__\n",
            "  File \"/usr/local/lib/python3.11/dist-packages/IPython/core/formatters.py\", line 224, in catch_format_error\n",
            "    r = method(self, *args, **kwargs)\n",
            "        ^^^^^^^^^^^^^^^^^^^^^^^^^^^^^\n",
            "  File \"/usr/local/lib/python3.11/dist-packages/IPython/core/formatters.py\", line 341, in __call__\n",
            "    return printer(obj)\n",
            "           ^^^^^^^^^^^^\n",
            "  File \"/usr/local/lib/python3.11/dist-packages/IPython/core/pylabtools.py\", line 151, in print_figure\n",
            "    fig.canvas.print_figure(bytes_io, **kw)\n",
            "  File \"/usr/local/lib/python3.11/dist-packages/matplotlib/backend_bases.py\", line 2155, in print_figure\n",
            "    self.figure.draw(renderer)\n",
            "  File \"/usr/local/lib/python3.11/dist-packages/matplotlib/artist.py\", line 94, in draw_wrapper\n",
            "    result = draw(artist, renderer, *args, **kwargs)\n",
            "             ^^^^^^^^^^^^^^^^^^^^^^^^^^^^^^^^^^^^^^^\n",
            "  File \"/usr/local/lib/python3.11/dist-packages/matplotlib/artist.py\", line 71, in draw_wrapper\n",
            "    return draw(artist, renderer)\n",
            "           ^^^^^^^^^^^^^^^^^^^^^^\n",
            "  File \"/usr/local/lib/python3.11/dist-packages/matplotlib/figure.py\", line 3257, in draw\n",
            "    mimage._draw_list_compositing_images(\n",
            "  File \"/usr/local/lib/python3.11/dist-packages/matplotlib/image.py\", line 134, in _draw_list_compositing_images\n",
            "    a.draw(renderer)\n",
            "  File \"/usr/local/lib/python3.11/dist-packages/matplotlib/artist.py\", line 71, in draw_wrapper\n",
            "    return draw(artist, renderer)\n",
            "           ^^^^^^^^^^^^^^^^^^^^^^\n",
            "  File \"/usr/local/lib/python3.11/dist-packages/cartopy/mpl/geoaxes.py\", line 524, in draw\n",
            "    return super().draw(renderer=renderer, **kwargs)\n",
            "           ^^^^^^^^^^^^^^^^^^^^^^^^^^^^^^^^^^^^^^^^^\n",
            "  File \"/usr/local/lib/python3.11/dist-packages/matplotlib/artist.py\", line 71, in draw_wrapper\n",
            "    return draw(artist, renderer)\n",
            "           ^^^^^^^^^^^^^^^^^^^^^^\n",
            "  File \"/usr/local/lib/python3.11/dist-packages/matplotlib/axes/_base.py\", line 3181, in draw\n",
            "    mimage._draw_list_compositing_images(\n",
            "  File \"/usr/local/lib/python3.11/dist-packages/matplotlib/image.py\", line 134, in _draw_list_compositing_images\n",
            "    a.draw(renderer)\n",
            "  File \"/usr/local/lib/python3.11/dist-packages/matplotlib/artist.py\", line 71, in draw_wrapper\n",
            "    return draw(artist, renderer)\n",
            "           ^^^^^^^^^^^^^^^^^^^^^^\n",
            "  File \"/usr/local/lib/python3.11/dist-packages/cartopy/mpl/feature_artist.py\", line 215, in draw\n",
            "    projected_geom = ax.projection.project_geometry(\n",
            "                     ^^^^^^^^^^^^^^^^^^^^^^^^^^^^^^^\n",
            "  File \"/usr/local/lib/python3.11/dist-packages/cartopy/crs.py\", line 827, in project_geometry\n",
            "    return getattr(self, method_name)(geometry, src_crs)\n",
            "           ^^^^^^^^^^^^^^^^^^^^^^^^^^^^^^^^^^^^^^^^^^^^^\n",
            "  File \"/usr/local/lib/python3.11/dist-packages/cartopy/crs.py\", line 960, in _project_polygon\n",
            "    p_rings, p_mline = self._project_linear_ring(src_ring, src_crs)\n",
            "                       ^^^^^^^^^^^^^^^^^^^^^^^^^^^^^^^^^^^^^^^^^^^^\n",
            "  File \"/usr/local/lib/python3.11/dist-packages/cartopy/crs.py\", line 846, in _project_linear_ring\n",
            "    multi_line_string = cartopy.trace.project_linear(linear_ring,\n",
            "                        ^^^^^^^^^^^^^^^^^^^^^^^^^^^^^^^^^^^^^^^^^\n",
            "KeyboardInterrupt\n",
            "\n",
            "During handling of the above exception, another exception occurred:\n",
            "\n",
            "Traceback (most recent call last):\n",
            "  File \"/usr/local/lib/python3.11/dist-packages/IPython/core/interactiveshell.py\", line 2099, in showtraceback\n",
            "    stb = value._render_traceback_()\n",
            "          ^^^^^^^^^^^^^^^^^^^^^^^^\n",
            "AttributeError: 'KeyboardInterrupt' object has no attribute '_render_traceback_'\n",
            "\n",
            "During handling of the above exception, another exception occurred:\n",
            "\n",
            "Traceback (most recent call last):\n",
            "  File \"/usr/local/lib/python3.11/dist-packages/IPython/core/ultratb.py\", line 1101, in get_records\n",
            "    return _fixed_getinnerframes(etb, number_of_lines_of_context, tb_offset)\n",
            "           ^^^^^^^^^^^^^^^^^^^^^^^^^^^^^^^^^^^^^^^^^^^^^^^^^^^^^^^^^^^^^^^^^\n",
            "  File \"/usr/local/lib/python3.11/dist-packages/IPython/core/ultratb.py\", line 248, in wrapped\n",
            "    return f(*args, **kwargs)\n",
            "           ^^^^^^^^^^^^^^^^^^\n",
            "  File \"/usr/local/lib/python3.11/dist-packages/IPython/core/ultratb.py\", line 281, in _fixed_getinnerframes\n",
            "    records = fix_frame_records_filenames(inspect.getinnerframes(etb, context))\n",
            "                                          ^^^^^^^^^^^^^^^^^^^^^^^^^^^^^^^^^^^^\n",
            "  File \"/usr/lib/python3.11/inspect.py\", line 1739, in getinnerframes\n",
            "    traceback_info = getframeinfo(tb, context)\n",
            "                     ^^^^^^^^^^^^^^^^^^^^^^^^^\n",
            "  File \"/usr/lib/python3.11/inspect.py\", line 1686, in getframeinfo\n",
            "    start = lineno - 1 - context//2\n",
            "            ~~~~~~~^~~\n",
            "TypeError: unsupported operand type(s) for -: 'NoneType' and 'int'\n"
          ]
        }
      ]
    },
    {
      "cell_type": "code",
      "source": [
        "def create_gif(image_folder, output_gif, duration=500):\n",
        "    images = []\n",
        "    for filename in sorted(os.listdir(image_folder)):\n",
        "        if filename.endswith((\".jpg\", \".jpeg\", \".png\", \".bmp\")):\n",
        "            filepath = os.path.join(image_folder, filename)\n",
        "            images.append(Image.open(filepath))\n",
        "\n",
        "    images[0].save(\n",
        "        output_gif,\n",
        "        save_all=True,\n",
        "        append_images=images[1:],\n",
        "        optimize=False,\n",
        "        duration=duration,\n",
        "        loop=0,\n",
        "    )\n",
        "\n",
        "if __name__ == \"__main__\":\n",
        "    image_folder = \"/content/img_files/\"\n",
        "    output_gif = \"fvcom_waterlwd.gif\"\n",
        "    create_gif(image_folder, output_gif)"
      ],
      "metadata": {
        "id": "h3Ha1EhmbiJ7"
      },
      "execution_count": 173,
      "outputs": []
    }
  ]
}